Workbook

Sheet Puntentelling
A1: Puntentelling WK Poule 2026
D3: Standen | E3: Bonus
C4: Uitslagen | D4: Poule | E4: Vragen | G4: Totaal
A6: 1 | B6: Thijs | C6: ='Groepsfase Thijs'!J82 -> 12
A7: =A6+1 -> 2 | B7: Emma | C7: ='Groepsfase Emma'!J82 -> 16
A8: =A7+1 -> 3 | B8: Tom | C8: ='Groepsfase Tom'!J82 -> 16
A9: =A8+1 -> 4 | B9: Nova | C9: ='Groepsfase Nova'!J82 -> 21
A10: =A9+1 -> 5 | B10: Koen N | C10: ='Groepsfase Koen N'!J82 -> 16
A11: =A10+1 -> 6 | B11: Frederique | C11: ='Groepsfase Frederique'!J82 -> 13
A12: =A11+1 -> 7 | B12: PP | C12: ='Groepsfase PP'!J82 -> 15
A13: =A12+1 -> 8 | B13: Gies | C13: ='Groepsfase Gies'!J82 -> 18
A14: =A13+1 -> 9 | B14: Guusje | C14: ='Groepsfase Guusje'!J82 -> 10
A15: =A14+1 -> 10 | B15: Esther | C15: ='Groepsfase Esther'!J82 -> 20
A16: =A15+1 -> 11 | B16: Pleun/Max | C16: ='Groepsfase Pleun'!J82 -> 11
A17: =A16+1 -> 12 | B17: Niek | C17: ='Groepsfase Niek'!J82 -> 15
A18: =A17+1 -> 13 | B18: Patrick | C18: ='Groepsfase Patrick'!J82 -> 18
A19: =A18+1 -> 14 | B19: Maartje | C19: ='Groepsfase Maartje'!J82 -> 15
A20: =A19+1 -> 15 | B20: Sam | C20: ='Groepsfase Sam'!J82 -> 14
A21: =A20+1 -> 16 | B21: Guus | C21: ='Groepsfase Guus'!J82 -> 20
A22: =A21+1 -> 17 | B22: Bram | C22: ='Groepsfase Bram'!J82 -> 15
A23: =A22+1 -> 18 | B23: Puck/Kiki | C23: ='Groepsfase Puck'!J82 -> 15
A24: =A23+1 -> 19 | B24: Mart | C24: ='Groepsfase Mart'!J82 -> 16
A25: =A24+1 -> 20 | B25: Jetski | C25: ='Groepsfase Jetski'!J82 -> 12
A26: =A25+1 -> 21 | B26: Dennis | C26: ='Groepsfase Dennis'!J82 -> 21
A27: =A26+1 -> 22 | B27: Froukje | C27: ='Groepsfase Froukje'!J82 -> 11
A28: =A27+1 -> 23 | B28: Edward | C28: ='Groepsfase Edward'!J82 -> 15
A29: =A28+1 -> 24 | B29: Lucas/Herwin | C29: ='Groepsfase Lucas'!J82 -> 14
A30: =A29+1 -> 25 | B30: Bobbi | C30: ='Groepsfase Bobbi'!J82 -> 15
A31: =A30+1 -> 26 | B31: Koen B | C31: ='Groepsfase Koen B'!J82 -> 12
A32: =A31+1 -> 27 | B32: Floris | C32: ='Groepsfase Floris'!J82 -> 22
A33: =A32+1 -> 28 | B33: Gijs | C33: ='Groepsfase Gijs'!J82 -> 15
A34: =A33+1 -> 29 | B34: Van der geize | C34: ='Groepsfase vd Geize'!J82 -> 18
A35: =A34+1 -> 30 | B35: Freek | C35: ='Groepsfase Freek'!J82 -> 22
A36: =A35+1 -> 31 | B36: Nanne | C36: ='Groepsfase Nanne'!J82 -> 17
A37: =A36+1 -> 32 | B37: Mats/Koen | C37: ='Groepsfase Mats'!J82 -> 19
A38: 33 | B38: Teun | C38: ='Groepsfase Teun'!J82 -> 16
A39: 34 | B39: Ollie | C39: ='Groepsfase Ollie'!J82 -> 13
A40: 35 | B40: AI | C40: ='Groepsfase AI'!J82 -> 10

Sheet Groepsfase Thijs
J6: Punten
A8: Nr | B8: Datum | C8: Groep | D8: Thuis | E8: T | F8: U | G8: Uit | H8: Res
A9: 1 | B9: 2026-06-11 | C9: A | D9: Mexico | E9: 3 | F9: 1 | G9: South Africa | H9: =IF(AND(E9<>"",F9<>""),IF(E9>F9,"H",IF(E9<F9,"A","D")),"") -> H | J9: 1
A10: 2 | B10: 2026-06-11 | C10: A | D10: South Korea | E10: 1 | F10: 0 | G10: Tsjechië | H10: =IF(AND(E10<>"",F10<>""),IF(E10>F10,"H",IF(E10<F10,"A","D")),"") -> H | J10: 1
A11: 3 | B11: 2026-06-18 | C11: A | D11: Tsjechië | E11: 2 | F11: 1 | G11: South Africa | H11: =IF(AND(E11<>"",F11<>""),IF(E11>F11,"H",IF(E11<F11,"A","D")),"") -> H
A12: 4 | B12: 2026-06-18 | C12: A | D12: Mexico | E12: 1 | F12: 0 | G12: South Korea | H12: =IF(AND(E12<>"",F12<>""),IF(E12>F12,"H",IF(E12<F12,"A","D")),"") -> H
A13: 5 | B13: 2026-06-24 | C13: A | D13: Tsjechië | E13: 0 | F13: 1 | G13: Mexico | H13: =IF(AND(E13<>"",F13<>""),IF(E13>F13,"H",IF(E13<F13,"A","D")),"") -> A
A14: 6 | B14: 2026-06-24 | C14: A | D14: South Africa | E14: 1 | F14: 0 | G14: South Korea | H14: =IF(AND(E14<>"",F14<>""),IF(E14>F14,"H",IF(E14<F14,"A","D")),"") -> H
A15: 7 | B15: 2026-06-12 | C15: B | D15: Canada | E15: 0 | F15: 2 | G15: Bosnië-Herzegovina | H15: =IF(AND(E15<>"",F15<>""),IF(E15>F15,"H",IF(E15<F15,"A","D")),"") -> A | J15: 0
A16: 8 | B16: 2026-06-13 | C16: B | D16: Qatar | E16: 0 | F16: 1 | G16: Switzerland | H16: =IF(AND(E16<>"",F16<>""),IF(E16>F16,"H",IF(E16<F16,"A","D")),"") -> A | J16: 0
A17: 9 | B17: 2026-06-18 | C17: B | D17: Switzerland | E17: 2 | F17: 1 | G17: Bosnië-Herzegovina | H17: =IF(AND(E17<>"",F17<>""),IF(E17>F17,"H",IF(E17<F17,"A","D")),"") -> H
A18: 10 | B18: 2026-06-18 | C18: B | D18: Canada | E18: 1 | F18: 1 | G18: Qatar | H18: =IF(AND(E18<>"",F18<>""),IF(E18>F18,"H",IF(E18<F18,"A","D")),"") -> D
A19: 11 | B19: 2026-06-24 | C19: B | D19: Switzerland | E19: 2 | F19: 1 | G19: Canada | H19: =IF(AND(E19<>"",F19<>""),IF(E19>F19,"H",IF(E19<F19,"A","D")),"") -> H
A20: 12 | B20: 2026-06-24 | C20: B | D20: Bosnië-Herzegovina | E20: 1 | F20: 0 | G20: Qatar | H20: =IF(AND(E20<>"",F20<>""),IF(E20>F20,"H",IF(E20<F20,"A","D")),"") -> H
A21: 13 | B21: 2026-06-13 | C21: C | D21: Brazil | E21: 1 | F21: 0 | G21: Morocco | H21: =IF(AND(E21<>"",F21<>""),IF(E21>F21,"H",IF(E21<F21,"A","D")),"") -> H | J21: 0
A22: 14 | B22: 2026-06-13 | C22: C | D22: Haiti | E22: 0 | F22: 2 | G22: Scotland | H22: =IF(AND(E22<>"",F22<>""),IF(E22>F22,"H",IF(E22<F22,"A","D")),"") -> A | J22: 1
A23: 15 | B23: 2026-06-19 | C23: C | D23: Scotland | E23: 0 | F23: 1 | G23: Morocco | H23: =IF(AND(E23<>"",F23<>""),IF(E23>F23,"H",IF(E23<F23,"A","D")),"") -> A
A24: 16 | B24: 2026-06-19 | C24: C | D24: Brazil | E24: 2 | F24: 0 | G24: Haiti | H24: =IF(AND(E24<>"",F24<>""),IF(E24>F24,"H",IF(E24<F24,"A","D")),"") -> H
A25: 17 | B25: 2026-06-24 | C25: C | D25: Scotland | E25: 0 | F25: 2 | G25: Brazil | H25: =IF(AND(E25<>"",F25<>""),IF(E25>F25,"H",IF(E25<F25,"A","D")),"") -> A
A26: 18 | B26: 2026-06-24 | C26: C | D26: Morocco | E26: 1 | F26: 0 | G26: Haiti | H26: =IF(AND(E26<>"",F26<>""),IF(E26>F26,"H",IF(E26<F26,"A","D")),"") -> H
A27: 19 | B27: 2026-06-12 | C27: D | D27: USA | E27: 2 | F27: 1 | G27: Paraguay | H27: =IF(AND(E27<>"",F27<>""),IF(E27>F27,"H",IF(E27<F27,"A","D")),"") -> H | J27: 1
A28: 20 | B28: 2026-06-13 | C28: D | D28: Australia | E28: 1 | F28: 2 | G28: Turkije | H28: =IF(AND(E28<>"",F28<>""),IF(E28>F28,"H",IF(E28<F28,"A","D")),"") -> A | J28: 0
A29: 21 | B29: 2026-06-19 | C29: D | D29: USA | E29: 2 | F29: 1 | G29: Australia | H29: =IF(AND(E29<>"",F29<>""),IF(E29>F29,"H",IF(E29<F29,"A","D")),"") -> H
A30: 22 | B30: 2026-06-19 | C30: D | D30: Turkije | E30: 2 | F30: 1 | G30: Paraguay | H30: =IF(AND(E30<>"",F30<>""),IF(E30>F30,"H",IF(E30<F30,"A","D")),"") -> H
A31: 23 | B31: 2026-06-25 | C31: D | D31: Turkije | E31: 2 | F31: 1 | G31: USA | H31: =IF(AND(E31<>"",F31<>""),IF(E31>F31,"H",IF(E31<F31,"A","D")),"") -> H
A32: 24 | B32: 2026-06-25 | C32: D | D32: Paraguay | E32: 1 | F32: 1 | G32: Australia | H32: =IF(AND(E32<>"",F32<>""),IF(E32>F32,"H",IF(E32<F32,"A","D")),"") -> D
A33: 25 | B33: 2026-06-14 | C33: E | D33: Germany | E33: 3 | F33: 1 | G33: Curaçao | H33: =IF(AND(E33<>"",F33<>""),IF(E33>F33,"H",IF(E33<F33,"A","D")),"") -> H | J33: 1
A34: 26 | B34: 2026-06-14 | C34: E | D34: Ivory Coast | E34: 2 | F34: 1 | G34: Ecuador | H34: =IF(AND(E34<>"",F34<>""),IF(E34>F34,"H",IF(E34<F34,"A","D")),"") -> H | J34: 1
A35: 27 | B35: 2026-06-20 | C35: E | D35: Germany | E35: 2 | F35: 1 | G35: Ivory Coast | H35: =IF(AND(E35<>"",F35<>""),IF(E35>F35,"H",IF(E35<F35,"A","D")),"") -> H
A36: 28 | B36: 2026-06-20 | C36: E | D36: Ecuador | E36: 1 | F36: 1 | G36: Curaçao | H36: =IF(AND(E36<>"",F36<>""),IF(E36>F36,"H",IF(E36<F36,"A","D")),"") -> D
A37: 29 | B37: 2026-06-25 | C37: E | D37: Ecuador | E37: 1 | F37: 2 | G37: Germany | H37: =IF(AND(E37<>"",F37<>""),IF(E37>F37,"H",IF(E37<F37,"A","D")),"") -> A
A38: 30 | B38: 2026-06-25 | C38: E | D38: Curaçao | E38: 1 | F38: 2 | G38: Ivory Coast | H38: =IF(AND(E38<>"",F38<>""),IF(E38>F38,"H",IF(E38<F38,"A","D")),"") -> A
A39: 31 | B39: 2026-06-14 | C39: F | D39: Netherlands | E39: 1 | F39: 1 | G39: Japan | H39: =IF(AND(E39<>"",F39<>""),IF(E39>F39,"H",IF(E39<F39,"A","D")),"") -> D | J39: 1
A40: 32 | B40: 2026-06-14 | C40: F | D40: Zweden | E40: 2 | F40: 1 | G40: Tunisia | H40: =IF(AND(E40<>"",F40<>""),IF(E40>F40,"H",IF(E40<F40,"A","D")),"") -> H | J40: 1
A41: 33 | B41: 2026-06-20 | C41: F | D41: Netherlands | E41: 2 | F41: 1 | G41: Zweden | H41: =IF(AND(E41<>"",F41<>""),IF(E41>F41,"H",IF(E41<F41,"A","D")),"") -> H
A42: 34 | B42: 2026-06-20 | C42: F | D42: Tunisia | E42: 0 | F42: 1 | G42: Japan | H42: =IF(AND(E42<>"",F42<>""),IF(E42>F42,"H",IF(E42<F42,"A","D")),"") -> A
A43: 35 | B43: 2026-06-25 | C43: F | D43: Japan | E43: 2 | F43: 1 | G43: Zweden | H43: =IF(AND(E43<>"",F43<>""),IF(E43>F43,"H",IF(E43<F43,"A","D")),"") -> H
A44: 36 | B44: 2026-06-25 | C44: F | D44: Tunisia | E44: 1 | F44: 2 | G44: Netherlands | H44: =IF(AND(E44<>"",F44<>""),IF(E44>F44,"H",IF(E44<F44,"A","D")),"") -> A
A45: 37 | B45: 2026-06-15 | C45: G | D45: Belgium | E45: 2 | F45: 1 | G45: Egypt | H45: =IF(AND(E45<>"",F45<>""),IF(E45>F45,"H",IF(E45<F45,"A","D")),"") -> H | J45: 0
A46: 38 | B46: 2026-06-15 | C46: G | D46: Iran | E46: 0 | F46: 1 | G46: New Zealand | H46: =IF(AND(E46<>"",F46<>""),IF(E46>F46,"H",IF(E46<F46,"A","D")),"") -> A | J46: 0
...

Sheet Knock-out Thijs
A8: Teams laatste 32 | D8: Teams laatste 16 | G8: Teams laatste 8 | J8: Teams laatste 4 | M8: Teams Finale | P8: Winnaar
A10: 1 | B10: nederland | D10: 1 | E10: nederland | G10: 1 | H10: nederland | J10: 1 | K10: nederland | M10: 1 | N10: nederland | P10: 1 | Q10: frankrijk
A11: =A10+1 -> 2 | B11: mexico | D11: =D10+1 -> 2 | E11: mexico | G11: =G10+1 -> 2 | H11: japan | J11: =J10+1 -> 2 | K11: japan | M11: =M10+1 -> 2 | N11: frankrijk
A12: =A11+1 -> 3 | B12: zuid korea | D12: =D11+1 -> 3 | E12: duitsland | G12: =G11+1 -> 3 | H12: zweden | J12: =J11+1 -> 3 | K12: frankrijk
A13: =A12+1 -> 4 | B13: canada | D13: =D12+1 -> 4 | E13: japan | G13: =G12+1 -> 4 | H13: engeland | J13: =J12+1 -> 4 | K13: mexico
A14: =A13+1 -> 5 | B14: bosnie | D14: =D13+1 -> 5 | E14: spanje | G14: =G13+1 -> 5 | H14: frankrijk
A15: =A14+1 -> 6 | B15: usa | D15: =D14+1 -> 6 | E15: belgie | G15: =G14+1 -> 6 | H15: spanje
A16: =A15+1 -> 7 | B16: paraguay | D16: =D15+1 -> 7 | E16: portugal | G16: =G15+1 -> 7 | H16: mexico
A17: =A16+1 -> 8 | B17: duitsland | D17: =D16+1 -> 8 | E17: argentinie | G17: =G16+1 -> 8 | H17: ghana
A18: =A17+1 -> 9 | B18: curacao | D18: =D17+1 -> 9 | E18: engeland
A19: =A18+1 -> 10 | B19: japan | D19: =D18+1 -> 10 | E19: zweden
A20: =A19+1 -> 11 | B20: belgie | D20: =D19+1 -> 11 | E20: turkije | H20: Bonus Vragen:
A21: =A20+1 -> 12 | B21: egytpte | D21: =D20+1 -> 12 | E21: frankrijk
A22: =A21+1 -> 13 | B22: spanje | D22: =D21+1 -> 13 | E22: kroatie | H22: 1. Topscoorder toernooi | K22: harry kane
A23: =A22+1 -> 14 | B23: kaapverdie | D23: =D22+1 -> 14 | E23: ghana | H23: 2. Land met 1e rode kaart | K23: zuid afrika
A24: =A23+1 -> 15 | B24: frankrijk | D24: =D23+1 -> 15 | E24: tjechie | H24: 3. Beste speler toernooi | K24: dumfries
A25: =A24+1 -> 16 | B25: senegal | D25: =D24+1 -> 16 | E25: paraguay
A26: =A25+1 -> 17 | B26: argentinie | H26: Totaal aantal doelpunten | K26: 214
A27: =A26+1 -> 18 | B27: algerije | H27: (bij gelijke stand)
A28: =A27+1 -> 19 | B28: portugal
A29: =A28+1 -> 20 | B29: congo
A30: =A29+1 -> 21 | B30: oezbekistan
A31: =A30+1 -> 22 | B31: engeland
A32: =A31+1 -> 23 | B32: kroatie
A33: =A32+1 -> 24 | B33: ghana
A34: =A33+1 -> 25 | B34: oostenrijk
A35: =A34+1 -> 26 | B35: noorwegen
A36: =A35+1 -> 27 | B36: colombia
A37: =A36+1 -> 28 | B37: uruguay
A38: =A37+1 -> 29 | B38: zweden
A39: =A38+1 -> 30 | B39: turkije
... A41: =A40+1 -> 32 | B41: tjechie

Sheet Groepsfase Emma
J6: Punten
A8: Nr | B8: Datum | C8: Groep | D8: Thuis | E8: T | F8: U | G8: Uit | H8: Res
A9: 1 | B9: 2026-06-11 | C9: A | D9: Mexico | E9: 2 | F9: 0 | G9: South Africa | H9: =IF(AND(E9<>"",F9<>""),IF(E9>F9,"H",IF(E9<F9,"A","D")),"") -> H | J9: 3
A10: 2 | B10: 2026-06-11 | C10: A | D10: South Korea | E10: 2 | F10: 1 | G10: Tsjechië | H10: =IF(AND(E10<>"",F10<>""),IF(E10>F10,"H",IF(E10<F10,"A","D")),"") -> H | J10: 3
A11: 3 | B11: 2026-06-18 | C11: A | D11: Tsjechië | E11: 2 | F11: 1 | G11: South Africa | H11: =IF(AND(E11<>"",F11<>""),IF(E11>F11,"H",IF(E11<F11,"A","D")),"") -> H
A12: 4 | B12: 2026-06-18 | C12: A | D12: Mexico | E12: 2 | F12: 1 | G12: South Korea | H12: =IF(AND(E12<>"",F12<>""),IF(E12>F12,"H",IF(E12<F12,"A","D")),"") -> H
A13: 5 | B13: 2026-06-24 | C13: A | D13: Tsjechië | E13: 1 | F13: 2 | G13: Mexico | H13: =IF(AND(E13<>"",F13<>""),IF(E13>F13,"H",IF(E13<F13,"A","D")),"") -> A
A14: 6 | B14: 2026-06-24 | C14: A | D14: South Africa | E14: 1 | F14: 2 | G14: South Korea | H14: =IF(AND(E14<>"",F14<>""),IF(E14>F14,"H",IF(E14<F14,"A","D")),"") -> A
A15: 7 | B15: 2026-06-12 | C15: B | D15: Canada | E15: 2 | F15: 1 | G15: Bosnië-Herzegovina | H15: =IF(AND(E15<>"",F15<>""),IF(E15>F15,"H",IF(E15<F15,"A","D")),"") -> H | J15: 0
A16: 8 | B16: 2026-06-13 | C16: B | D16: Qatar | E16: 0 | F16: 2 | G16: Switzerland | H16: =IF(AND(E16<>"",F16<>""),IF(E16>F16,"H",IF(E16<F16,"A","D")),"") -> A | J16: 0
A17: 9 | B17: 2026-06-18 | C17: B | D17: Switzerland | E17: 2 | F17: 1 | G17: Bosnië-Herzegovina | H17: =IF(AND(E17<>"",F17<>""),IF(E17>F17,"H",IF(E17<F17,"A","D")),"") -> H
A18: 10 | B18: 2026-06-18 | C18: B | D18: Canada | E18: 3 | F18: 0 | G18: Qatar | H18: =IF(AND(E18<>"",F18<>""),IF(E18>F18,"H",IF(E18<F18,"A","D")),"") -> H
A19: 11 | B19: 2026-06-24 | C19: B | D19: Switzerland | E19: 1 | F19: 1 | G19: Canada | H19: =IF(AND(E19<>"",F19<>""),IF(E19>F19,"H",IF(E19<F19,"A","D")),"") -> D
A20: 12 | B20: 2026-06-24 | C20: B | D20: Bosnië-Herzegovina | E20: 2 | F20: 1 | G20: Qatar | H20: =IF(AND(E20<>"",F20<>""),IF(E20>F20,"H",IF(E20<F20,"A","D")),"") -> H
A21: 13 | B21: 2026-06-13 | C21: C | D21: Brazil | E21: 2 | F21: 0 | G21: Morocco | H21: =IF(AND(E21<>"",F21<>""),IF(E21>F21,"H",IF(E21<F21,"A","D")),"") -> H | J21: 0
A22: 14 | B22: 2026-06-13 | C22: C | D22: Haiti | E22: 1 | F22: 2 | G22: Scotland | H22: =IF(AND(E22<>"",F22<>""),IF(E22>F22,"H",IF(E22<F22,"A","D")),"") -> A | J22: 1
A23: 15 | B23: 2026-06-19 | C23: C | D23: Scotland | E23: 1 | F23: 2 | G23: Morocco | H23: =IF(AND(E23<>"",F23<>""),IF(E23>F23,"H",IF(E23<F23,"A","D")),"") -> A
A24: 16 | B24: 2026-06-19 | C24: C | D24: Brazil | E24: 4 | F24: 0 | G24: Haiti | H24: =IF(AND(E24<>"",F24<>""),IF(E24>F24,"H",IF(E24<F24,"A","D")),"") -> H
A25: 17 | B25: 2026-06-24 | C25: C | D25: Scotland | E25: 0 | F25: 4 | G25: Brazil | H25: =IF(AND(E25<>"",F25<>""),IF(E25>F25,"H",IF(E25<F25,"A","D")),"") -> A
A26: 18 | B26: 2026-06-24 | C26: C | D26: Morocco | E26: 2 | F26: 0 | G26: Haiti | H26: =IF(AND(E26<>"",F26<>""),IF(E26>F26,"H",IF(E26<F26,"A","D")),"") -> H
A27: 19 | B27: 2026-06-12 | C27: D | D27: USA | E27: 2 | F27: 0 | G27: Paraguay | H27: =IF(AND(E27<>"",F27<>""),IF(E27>F27,"H",IF(E27<F27,"A","D")),"") -> H | J27: 1
A28: 20 | B28: 2026-06-13 | C28: D | D28: Australia | E28: 1 | F28: 2 | G28: Turkije | H28: =IF(AND(E28<>"",F28<>""),IF(E28>F28,"H",IF(E28<F28,"A","D")),"") -> A | J28: 0
A29: 21 | B29: 2026-06-19 | C29: D | D29: USA | E29: 2 | F29: 0 | G29: Australia | H29: =IF(AND(E29<>"",F29<>""),IF(E29>F29,"H",IF(E29<F29,"A","D")),"") -> H
A30: 22 | B30: 2026-06-19 | C30: D | D30: Turkije | E30: 2 | F30: 1 | G30: Paraguay | H30: =IF(AND(E30<>"",F30<>""),IF(E30>F30,"H",IF(E30<F30,"A","D")),"") -> H
A31: 23 | B31: 2026-06-25 | C31: D | D31: Turkije | E31: 1 | F31: 2 | G31: USA | H31: =IF(AND(E31<>"",F31<>""),IF(E31>F31,"H",IF(E31<F31,"A","D")),"") -> A
A32: 24 | B32: 2026-06-25 | C32: D | D32: Paraguay | E32: 1 | F32: 1 | G32: Australia | H32: =IF(AND(E32<>"",F32<>""),IF(E32>F32,"H",IF(E32<F32,"A","D")),"") -> D
A33: 25 | B33: 2026-06-14 | C33: E | D33: Germany | E33: 4 | F33: 0 | G33: Curaçao | H33: =IF(AND(E33<>"",F33<>""),IF(E33>F33,"H",IF(E33<F33,"A","D")),"") -> H | J33: 1
A34: 26 | B34: 2026-06-14 | C34: E | D34: Ivory Coast | E34: 1 | F34: 1 | G34: Ecuador | H34: =IF(AND(E34<>"",F34<>""),IF(E34>F34,"H",IF(E34<F34,"A","D")),"") -> D | J34: 0
A35: 27 | B35: 2026-06-20 | C35: E | D35: Germany | E35: 4 | F35: 0 | G35: Ivory Coast | H35: =IF(AND(E35<>"",F35<>""),IF(E35>F35,"H",IF(E35<F35,"A","D")),"") -> H
A36: 28 | B36: 2026-06-20 | C36: E | D36: Ecuador | E36: 2 | F36: 1 | G36: Curaçao | H36: =IF(AND(E36<>"",F36<>""),IF(E36>F36,"H",IF(E36<F36,"A","D")),"") -> H
A37: 29 | B37: 2026-06-25 | C37: E | D37: Ecuador | E37: 0 | F37: 4 | G37: Germany | H37: =IF(AND(E37<>"",F37<>""),IF(E37>F37,"H",IF(E37<F37,"A","D")),"") -> A
A38: 30 | B38: 2026-06-25 | C38: E | D38: Curaçao | E38: 1 | F38: 2 | G38: Ivory Coast | H38: =IF(AND(E38<>"",F38<>""),IF(E38>F38,"H",IF(E38<F38,"A","D")),"") -> A
A39: 31 | B39: 2026-06-14 | C39: F | D39: Netherlands | E39: 2 | F39: 1 | G39: Japan | H39: =IF(AND(E39<>"",F39<>""),IF(E39>F39,"H",IF(E39<F39,"A","D")),"") -> H | J39: 0
A40: 32 | B40: 2026-06-14 | C40: F | D40: Zweden | E40: 1 | F40: 1 | G40: Tunisia | H40: =IF(AND(E40<>"",F40<>""),IF(E40>F40,"H",IF(E40<F40,"A","D")),"") -> D | J40: 0
A41: 33 | B41: 2026-06-20 | C41: F | D41: Netherlands | E41: 2 | F41: 0 | G41: Zweden | H41: =IF(AND(E41<>"",F41<>""),IF(E41>F41,"H",IF(E41<F41,"A","D")),"") -> H
A42: 34 | B42: 2026-06-20 | C42: F | D42: Tunisia | E42: 1 | F42: 2 | G42: Japan | H42: =IF(AND(E42<>"",F42<>""),IF(E42>F42,"H",IF(E42<F42,"A","D")),"") -> A
A43: 35 | B43: 2026-06-25 | C43: F | D43: Japan | E43: 2 | F43: 1 | G43: Zweden | H43: =IF(AND(E43<>"",F43<>""),IF(E43>F43,"H",IF(E43<F43,"A","D")),"") -> H
A44: 36 | B44: 2026-06-25 | C44: F | D44: Tunisia | E44: 0 | F44: 2 | G44: Netherlands | H44: =IF(AND(E44<>"",F44<>""),IF(E44>F44,"H",IF(E44<F44,"A","D")),"") -> A
A45: 37 | B45: 2026-06-15 | C45: G | D45: Belgium | E45: 2 | F45: 0 | G45: Egypt | H45: =IF(AND(E45<>"",F45<>""),IF(E45>F45,"H",IF(E45<F45,"A","D")),"") -> H | J45: 0
A46: 38 | B46: 2026-06-15 | C46: G | D46: Iran | E46: 2 | F46: 1 | G46: New Zealand | H46: =IF(AND(E46<>"",F46<>""),IF(E46>F46,"H",IF(E46<F46,"A","D")),"") -> H | J46: 0
...

Sheet Knock-out Emma 
A8: Teams laatste 32 | D8: Teams laatste 16 | G8: Teams laatste 8 | J8: Teams laatste 4 | M8: Teams Finale | P8: Winnaar
A10: 1 | B10: Mexico | D10: 1 | E10: France | G10: 1 | H10: France | J10: 1 | K10: France | M10: 1 | N10: France | P10: 1 | Q10: France
A11: =A10+1 -> 2 | B11: South Korea | D11: =D10+1 -> 2 | E11: England | G11: =G10+1 -> 2 | H11: England | J11: =J10+1 -> 2 | K11: Spain | M11: =M10+1 -> 2 | N11: Brazil
A12: =A11+1 -> 3 | B12: Canada | D12: =D11+1 -> 3 | E12: Spain | G12: =G11+1 -> 3 | H12: Spain | J12: =J11+1 -> 3 | K12: Brazil
A13: =A12+1 -> 4 | B13: Switzerland | D13: =D12+1 -> 4 | E13: Portugal | G13: =G12+1 -> 4 | H13: Portugal | J13: =J12+1 -> 4 | K13: Germany
A14: =A13+1 -> 5 | B14: Brazil | D14: =D13+1 -> 5 | E14: Brazil | G14: =G13+1 -> 5 | H14: Brazil
A15: =A14+1 -> 6 | B15: Morocco | D15: =D14+1 -> 6 | E15: Argentina | G15: =G14+1 -> 6 | H15: Argentina
A16: =A15+1 -> 7 | B16: USA | D16: =D15+1 -> 7 | E16: Germany | G16: =G15+1 -> 7 | H16: Germany
A17: =A16+1 -> 8 | B17: Turkey | D17: =D16+1 -> 8 | E17: Uruguay | G17: =G16+1 -> 8 | H17: Uruguay
A18: =A17+1 -> 9 | B18: Germany | D18: =D17+1 -> 9 | E18: Netherlands
A19: =A18+1 -> 10 | B19: Ecuador | D19: =D18+1 -> 10 | E19: USA
A20: =A19+1 -> 11 | B20: Netherlands | D20: =D19+1 -> 11 | E20: Belgium | H20: Bonus Vragen:
A21: =A20+1 -> 12 | B21: Japan | D21: =D20+1 -> 12 | E21: Morocco
A22: =A21+1 -> 13 | B22: Belgium | D22: =D21+1 -> 13 | E22: Mexico | H22: 1. Topscoorder toernooi | I22: Harry Kane (England)
A23: =A22+1 -> 14 | B23: Egypt | D23: =D22+1 -> 14 | E23: Colombia | H23: 2. Land met 1e rode kaart | I23: Uruguay
A24: =A23+1 -> 15 | B24: Spain | D24: =D23+1 -> 15 | E24: Japan | H24: 3. Beste speler toernooi | I24: Lamine Yamal (Spain)
A25: =A24+1 -> 16 | B25: Uruguay | D25: =D24+1 -> 16 | E25: Croatia
A26: =A25+1 -> 17 | B26: France | H26: Totaal aantal doelpunten | I26: 274
A27: =A26+1 -> 18 | B27: Norway | H27: (bij gelijke stand)
A28: =A27+1 -> 19 | B28: Argentina
A29: =A28+1 -> 20 | B29: Austria
A30: =A29+1 -> 21 | B30: Portugal
A31: =A30+1 -> 22 | B31: Colombia
A32: =A31+1 -> 23 | B32: England
A33: =A32+1 -> 24 | B33: Croatia
A34: =A33+1 -> 25 | B34: Tsjechië
A35: =A34+1 -> 26 | B35: Bosnië-Herzegovina
A36: =A35+1 -> 27 | B36: Scotland
A37: =A36+1 -> 28 | B37: Paraguay
A38: =A37+1 -> 29 | B38: Ivory Coast
A39: =A38+1 -> 30 | B39: Sweden
... A41: =A40+1 -> 32 | B41: Senegal

Sheet Groepsfase Tom
J6: Punten
A8: Nr | B8: Datum | C8: Groep | D8: Thuis | E8: T | F8: U | G8: Uit | H8: Res
A9: 1 | B9: 2026-06-11 | C9: A | D9: Mexico | E9: 2 | F9: 0 | G9: South Africa | H9: =IF(AND(E9<>"",F9<>""),IF(E9>F9,"H",IF(E9<F9,"A","D")),"") -> H | J9: 3
A10: 2 | B10: 2026-06-11 | C10: A | D10: South Korea | E10: 2 | F10: 1 | G10: Tsjechië | H10: =IF(AND(E10<>"",F10<>""),IF(E10>F10,"H",IF(E10<F10,"A","D")),"") -> H | J10: 3
A11: 3 | B11: 2026-06-18 | C11: A | D11: Tsjechië | E11: 2 | F11: 1 | G11: South Africa | H11: =IF(AND(E11<>"",F11<>""),IF(E11>F11,"H",IF(E11<F11,"A","D")),"") -> H
A12: 4 | B12: 2026-06-18 | C12: A | D12: Mexico | E12: 2 | F12: 1 | G12: South Korea | H12: =IF(AND(E12<>"",F12<>""),IF(E12>F12,"H",IF(E12<F12,"A","D")),"") -> H
A13: 5 | B13: 2026-06-24 | C13: A | D13: Tsjechië | E13: 1 | F13: 2 | G13: Mexico | H13: =IF(AND(E13<>"",F13<>""),IF(E13>F13,"H",IF(E13<F13,"A","D")),"") -> A
A14: 6 | B14: 2026-06-24 | C14: A | D14: South Africa | E14: 1 | F14: 2 | G14: South Korea | H14: =IF(AND(E14<>"",F14<>""),IF(E14>F14,"H",IF(E14<F14,"A","D")),"") -> A
A15: 7 | B15: 2026-06-12 | C15: B | D15: Canada | E15: 2 | F15: 1 | G15: Bosnië-Herzegovina | H15: =IF(AND(E15<>"",F15<>""),IF(E15>F15,"H",IF(E15<F15,"A","D")),"") -> H | J15: 0
A16: 8 | B16: 2026-06-13 | C16: B | D16: Qatar | E16: 0 | F16: 2 | G16: Switzerland | H16: =IF(AND(E16<>"",F16<>""),IF(E16>F16,"H",IF(E16<F16,"A","D")),"") -> A | J16: 0
A17: 9 | B17: 2026-06-18 | C17: B | D17: Switzerland | E17: 2 | F17: 1 | G17: Bosnië-Herzegovina | H17: =IF(AND(E17<>"",F17<>""),IF(E17>F17,"H",IF(E17<F17,"A","D")),"") -> H
A18: 10 | B18: 2026-06-18 | C18: B | D18: Canada | E18: 3 | F18: 0 | G18: Qatar | H18: =IF(AND(E18<>"",F18<>""),IF(E18>F18,"H",IF(E18<F18,"A","D")),"") -> H
A19: 11 | B19: 2026-06-24 | C19: B | D19: Switzerland | E19: 1 | F19: 1 | G19: Canada | H19: =IF(AND(E19<>"",F19<>""),IF(E19>F19,"H",IF(E19<F19,"A","D")),"") -> D
A20: 12 | B20: 2026-06-24 | C20: B | D20: Bosnië-Herzegovina | E20: 2 | F20: 1 | G20: Qatar | H20: =IF(AND(E20<>"",F20<>""),IF(E20>F20,"H",IF(E20<F20,"A","D")),"") -> H
A21: 13 | B21: 2026-06-13 | C21: C | D21: Brazil | E21: 2 | F21: 0 | G21: Morocco | H21: =IF(AND(E21<>"",F21<>""),IF(E21>F21,"H",IF(E21<F21,"A","D")),"") -> H | J21: 0
A22: 14 | B22: 2026-06-13 | C22: C | D22: Haiti | E22: 1 | F22: 2 | G22: Scotland | H22: =IF(AND(E22<>"",F22<>""),IF(E22>F22,"H",IF(E22<F22,"A","D")),"") -> A | J22: 1
A23: 15 | B23: 2026-06-19 | C23: C | D23: Scotland | E23: 1 | F23: 2 | G23: Morocco | H23: =IF(AND(E23<>"",F23<>""),IF(E23>F23,"H",IF(E23<F23,"A","D")),"") -> A
A24: 16 | B24: 2026-06-19 | C24: C | D24: Brazil | E24: 4 | F24: 0 | G24: Haiti | H24: =IF(AND(E24<>"",F24<>""),IF(E24>F24,"H",IF(E24<F24,"A","D")),"") -> H
A25: 17 | B25: 2026-06-24 | C25: C | D25: Scotland | E25: 0 | F25: 4 | G25: Brazil | H25: =IF(AND(E25<>"",F25<>""),IF(E25>F25,"H",IF(E25<F25,"A","D")),"") -> A
A26: 18 | B26: 2026-06-24 | C26: C | D26: Morocco | E26: 2 | F26: 0 | G26: Haiti | H26: =IF(AND(E26<>"",F26<>""),IF(E26>F26,"H",IF(E26<F26,"A","D")),"") -> H
A27: 19 | B27: 2026-06-12 | C27: D | D27: USA | E27: 2 | F27: 0 | G27: Paraguay | H27: =IF(AND(E27<>"",F27<>""),IF(E27>F27,"H",IF(E27<F27,"A","D")),"") -> H | J27: 1
A28: 20 | B28: 2026-06-13 | C28: D | D28: Australia | E28: 1 | F28: 2 | G28: Turkije | H28: =IF(AND(E28<>"",F28<>""),IF(E28>F28,"H",IF(E28<F28,"A","D")),"") -> A | J28: 0
A29: 21 | B29: 2026-06-19 | C29: D | D29: USA | E29: 2 | F29: 0 | G29: Australia | H29: =IF(AND(E29<>"",F29<>""),IF(E29>F29,"H",IF(E29<F29,"A","D")),"") -> H
A30: 22 | B30: 2026-06-19 | C30: D | D30: Turkije | E30: 2 | F30: 1 | G30: Paraguay | H30: =IF(AND(E30<>"",F30<>""),IF(E30>F30,"H",IF(E30<F30,"A","D")),"") -> H
A31: 23 | B31: 2026-06-25 | C31: D | D31: Turkije | E31: 1 | F31: 2 | G31: USA | H31: =IF(AND(E31<>"",F31<>""),IF(E31>F31,"H",IF(E31<F31,"A","D")),"") -> A
A32: 24 | B32: 2026-06-25 | C32: D | D32: Paraguay | E32: 1 | F32: 1 | G32: Australia | H32: =IF(AND(E32<>"",F32<>""),IF(E32>F32,"H",IF(E32<F32,"A","D")),"") -> D
A33: 25 | B33: 2026-06-14 | C33: E | D33: Germany | E33: 4 | F33: 0 | G33: Curaçao | H33: =IF(AND(E33<>"",F33<>""),IF(E33>F33,"H",IF(E33<F33,"A","D")),"") -> H | J33: 1
A34: 26 | B34: 2026-06-14 | C34: E | D34: Ivory Coast | E34: 1 | F34: 1 | G34: Ecuador | H34: =IF(AND(E34<>"",F34<>""),IF(E34>F34,"H",IF(E34<F34,"A","D")),"") -> D | J34: 0
A35: 27 | B35: 2026-06-20 | C35: E | D35: Germany | E35: 4 | F35: 0 | G35: Ivory Coast | H35: =IF(AND(E35<>"",F35<>""),IF(E35>F35,"H",IF(E35<F35,"A","D")),"") -> H
A36: 28 | B36: 2026-06-20 | C36: E | D36: Ecuador | E36: 2 | F36: 1 | G36: Curaçao | H36: =IF(AND(E36<>"",F36<>""),IF(E36>F36,"H",IF(E36<F36,"A","D")),"") -> H
A37: 29 | B37: 2026-06-25 | C37: E | D37: Ecuador | E37: 0 | F37: 4 | G37: Germany | H37: =IF(AND(E37<>"",F37<>""),IF(E37>F37,"H",IF(E37<F37,"A","D")),"") -> A
A38: 30 | B38: 2026-06-25 | C38: E | D38: Curaçao | E38: 1 | F38: 2 | G38: Ivory Coast | H38: =IF(AND(E38<>"",F38<>""),IF(E38>F38,"H",IF(E38<F38,"A","D")),"") -> A
A39: 31 | B39: 2026-06-14 | C39: F | D39: Netherlands | E39: 2 | F39: 1 | G39: Japan | H39: =IF(AND(E39<>"",F39<>""),IF(E39>F39,"H",IF(E39<F39,"A","D")),"") -> H | J39: 0
A40: 32 | B40: 2026-06-14 | C40: F | D40: Zweden | E40: 1 | F40: 1 | G40: Tunisia | H40: =IF(AND(E40<>"",F40<>""),IF(E40>F40,"H",IF(E40<F40,"A","D")),"") -> D | J40: 0
A41: 33 | B41: 2026-06-20 | C41: F | D41: Netherlands | E41: 2 | F41: 0 | G41: Zweden | H41: =IF(AND(E41<>"",F41<>""),IF(E41>F41,"H",IF(E41<F41,"A","D")),"") -> H
A42: 34 | B42: 2026-06-20 | C42: F | D42: Tunisia | E42: 1 | F42: 2 | G42: Japan | H42: =IF(AND(E42<>"",F42<>""),IF(E42>F42,"H",IF(E42<F42,"A","D")),"") -> A
A43: 35 | B43: 2026-06-25 | C43: F | D43: Japan | E43: 2 | F43: 1 | G43: Zweden | H43: =IF(AND(E43<>"",F43<>""),IF(E43>F43,"H",IF(E43<F43,"A","D")),"") -> H
A44: 36 | B44: 2026-06-25 | C44: F | D44: Tunisia | E44: 0 | F44: 2 | G44: Netherlands | H44: =IF(AND(E44<>"",F44<>""),IF(E44>F44,"H",IF(E44<F44,"A","D")),"") -> A
A45: 37 | B45: 2026-06-15 | C45: G | D45: Belgium | E45: 2 | F45: 0 | G45: Egypt | H45: =IF(AND(E45<>"",F45<>""),IF(E45>F45,"H",IF(E45<F45,"A","D")),"") -> H | J45: 0
A46: 38 | B46: 2026-06-15 | C46: G | D46: Iran | E46: 2 | F46: 1 | G46: New Zealand | H46: =IF(AND(E46<>"",F46<>""),IF(E46>F46,"H",IF(E46<F46,"A","D")),"") -> H | J46: 0
...

Sheet Knock-out Tom 
A8: Teams laatste 32 | D8: Teams laatste 16 | G8: Teams laatste 8 | J8: Teams laatste 4 | M8: Teams Finale | P8: Winnaar
A10: 1 | B10: Mexico | D10: 1 | E10: Germany | G10: 1 | H10: Germany | J10: 1 | K10: Germany | M10: 1 | N10: Germany | P10: 1 | Q10: Germany
A11: =A10+1 -> 2 | B11: South Korea | D11: =D10+1 -> 2 | E11: France | G11: =G10+1 -> 2 | H11: France | J11: =J10+1 -> 2 | K11: France | M11: =M10+1 -> 2 | N11: France
A12: =A11+1 -> 3 | B12: Canada | D12: =D11+1 -> 3 | E12: Argentina | G12: =G11+1 -> 3 | H12: Argentina | J12: =J11+1 -> 3 | K12: England
A13: =A12+1 -> 4 | B13: Switzerland | D13: =D12+1 -> 4 | E13: England | G13: =G12+1 -> 4 | H13: England | J13: =J12+1 -> 4 | K13: Spain
A14: =A13+1 -> 5 | B14: Brazil | D14: =D13+1 -> 5 | E14: Netherlands | G14: =G13+1 -> 5 | H14: Brazil
A15: =A14+1 -> 6 | B15: Morocco | D15: =D14+1 -> 6 | E15: Brazil | G15: =G14+1 -> 6 | H15: Spain
A16: =A15+1 -> 7 | B16: USA | D16: =D15+1 -> 7 | E16: Spain | G16: =G15+1 -> 7 | H16: Portugal
A17: =A16+1 -> 8 | B17: Turkey | D17: =D16+1 -> 8 | E17: Portugal | G17: =G16+1 -> 8 | H17: Uruguay
A18: =A17+1 -> 9 | B18: Germany | D18: =D17+1 -> 9 | E18: USA
A19: =A18+1 -> 10 | B19: Ecuador | D19: =D18+1 -> 10 | E19: Belgium
A20: =A19+1 -> 11 | B20: Netherlands | D20: =D19+1 -> 11 | E20: Mexico | H20: Bonus Vragen:
A21: =A20+1 -> 12 | B21: Japan | D21: =D20+1 -> 12 | E21: Morocco
A22: =A21+1 -> 13 | B22: Belgium | D22: =D21+1 -> 13 | E22: Uruguay | H22: 1. Topscoorder toernooi | I22: Harry Kane (England)
A23: =A22+1 -> 14 | B23: Egypt | D23: =D22+1 -> 14 | E23: Japan | H23: 2. Land met 1e rode kaart | I23: Saudi Arabia
A24: =A23+1 -> 15 | B24: Spain | D24: =D23+1 -> 15 | E24: Croatia | H24: 3. Beste speler toernooi | I24: Lamine Yamal (Spain)
A25: =A24+1 -> 16 | B25: Uruguay | D25: =D24+1 -> 16 | E25: Colombia
A26: =A25+1 -> 17 | B26: France | H26: Totaal aantal doelpunten | I26: 274
A27: =A26+1 -> 18 | B27: Norway | H27: (bij gelijke stand)
A28: =A27+1 -> 19 | B28: Argentina
A29: =A28+1 -> 20 | B29: Austria
A30: =A29+1 -> 21 | B30: Portugal
A31: =A30+1 -> 22 | B31: Colombia
A32: =A31+1 -> 23 | B32: England
A33: =A32+1 -> 24 | B33: Croatia
A34: =A33+1 -> 25 | B34: Tsjechië
A35: =A34+1 -> 26 | B35: Bosnië-Herzegovina
A36: =A35+1 -> 27 | B36: Scotland
A37: =A36+1 -> 28 | B37: Paraguay
A38: =A37+1 -> 29 | B38: Ivory Coast
A39: =A38+1 -> 30 | B39: Sweden
... A41: =A40+1 -> 32 | B41: Senegal

Sheet Groepsfase Nova
J6: Punten
A8: Nr | B8: Datum | C8: Groep | D8: Thuis | E8: T | F8: U | G8: Uit | H8: Res
A9: 1 | B9: 2026-06-11 | C9: A | D9: Mexico | E9: 2 | F9: 0 | G9: South Africa | H9: =IF(AND(E9<>"",F9<>""),IF(E9>F9,"H",IF(E9<F9,"A","D")),"") -> H | J9: 3
A10: 2 | B10: 2026-06-11 | C10: A | D10: South Korea | E10: 1 | F10: 2 | G10: Tsjechië | H10: =IF(AND(E10<>"",F10<>""),IF(E10>F10,"H",IF(E10<F10,"A","D")),"") -> A | J10: 0
A11: 3 | B11: 2026-06-18 | C11: A | D11: Tsjechië | E11: 2 | F11: 0 | G11: South Africa | H11: =IF(AND(E11<>"",F11<>""),IF(E11>F11,"H",IF(E11<F11,"A","D")),"") -> H
A12: 4 | B12: 2026-06-18 | C12: A | D12: Mexico | E12: 2 | F12: 0 | G12: South Korea | H12: =IF(AND(E12<>"",F12<>""),IF(E12>F12,"H",IF(E12<F12,"A","D")),"") -> H
A13: 5 | B13: 2026-06-24 | C13: A | D13: Tsjechië | E13: 1 | F13: 2 | G13: Mexico | H13: =IF(AND(E13<>"",F13<>""),IF(E13>F13,"H",IF(E13<F13,"A","D")),"") -> A
A14: 6 | B14: 2026-06-24 | C14: A | D14: South Africa | E14: 2 | F14: 1 | G14: South Korea | H14: =IF(AND(E14<>"",F14<>""),IF(E14>F14,"H",IF(E14<F14,"A","D")),"") -> H
A15: 7 | B15: 2026-06-12 | C15: B | D15: Canada | E15: 1 | F15: 1 | G15: Bosnië-Herzegovina | H15: =IF(AND(E15<>"",F15<>""),IF(E15>F15,"H",IF(E15<F15,"A","D")),"") -> D | J15: 3
A16: 8 | B16: 2026-06-13 | C16: B | D16: Qatar | E16: 0 | F16: 2 | G16: Switzerland | H16: =IF(AND(E16<>"",F16<>""),IF(E16>F16,"H",IF(E16<F16,"A","D")),"") -> A | J16: 0
A17: 9 | B17: 2026-06-18 | C17: B | D17: Switzerland | E17: 1 | F17: 0 | G17: Bosnië-Herzegovina | H17: =IF(AND(E17<>"",F17<>""),IF(E17>F17,"H",IF(E17<F17,"A","D")),"") -> H
A18: 10 | B18: 2026-06-18 | C18: B | D18: Canada | E18: 2 | F18: 0 | G18: Qatar | H18: =IF(AND(E18<>"",F18<>""),IF(E18>F18,"H",IF(E18<F18,"A","D")),"") -> H
A19: 11 | B19: 2026-06-24 | C19: B | D19: Switzerland | E19: 2 | F19: 1 | G19: Canada | H19: =IF(AND(E19<>"",F19<>""),IF(E19>F19,"H",IF(E19<F19,"A","D")),"") -> H
A20: 12 | B20: 2026-06-24 | C20: B | D20: Bosnië-Herzegovina | E20: 2 | F20: 0 | G20: Qatar | H20: =IF(AND(E20<>"",F20<>""),IF(E20>F20,"H",IF(E20<F20,"A","D")),"") -> H
A21: 13 | B21: 2026-06-13 | C21: C | D21: Brazil | E21: 1 | F21: 1 | G21: Morocco | H21: =IF(AND(E21<>"",F21<>""),IF(E21>F21,"H",IF(E21<F21,"A","D")),"") -> D | J21: 3
A22: 14 | B22: 2026-06-13 | C22: C | D22: Haiti | E22: 0 | F22: 2 | G22: Scotland | H22: =IF(AND(E22<>"",F22<>""),IF(E22>F22,"H",IF(E22<F22,"A","D")),"") -> A | J22: 1
A23: 15 | B23: 2026-06-19 | C23: C | D23: Scotland | E23: 0 | F23: 1 | G23: Morocco | H23: =IF(AND(E23<>"",F23<>""),IF(E23>F23,"H",IF(E23<F23,"A","D")),"") -> A
A24: 16 | B24: 2026-06-19 | C24: C | D24: Brazil | E24: 4 | F24: 1 | G24: Haiti | H24: =IF(AND(E24<>"",F24<>""),IF(E24>F24,"H",IF(E24<F24,"A","D")),"") -> H
A25: 17 | B25: 2026-06-24 | C25: C | D25: Scotland | E25: 1 | F25: 2 | G25: Brazil | H25: =IF(AND(E25<>"",F25<>""),IF(E25>F25,"H",IF(E25<F25,"A","D")),"") -> A
A26: 18 | B26: 2026-06-24 | C26: C | D26: Morocco | E26: 3 | F26: 1 | G26: Haiti | H26: =IF(AND(E26<>"",F26<>""),IF(E26>F26,"H",IF(E26<F26,"A","D")),"") -> H
A27: 19 | B27: 2026-06-12 | C27: D | D27: USA | E27: 2 | F27: 0 | G27: Paraguay | H27: =IF(AND(E27<>"",F27<>""),IF(E27>F27,"H",IF(E27<F27,"A","D")),"") -> H | J27: 1
A28: 20 | B28: 2026-06-13 | C28: D | D28: Australia | E28: 1 | F28: 2 | G28: Turkije | H28: =IF(AND(E28<>"",F28<>""),IF(E28>F28,"H",IF(E28<F28,"A","D")),"") -> A | J28: 0
A29: 21 | B29: 2026-06-19 | C29: D | D29: USA | E29: 2 | F29: 1 | G29: Australia | H29: =IF(AND(E29<>"",F29<>""),IF(E29>F29,"H",IF(E29<F29,"A","D")),"") -> H
A30: 22 | B30: 2026-06-19 | C30: D | D30: Turkije | E30: 2 | F30: 0 | G30: Paraguay | H30: =IF(AND(E30<>"",F30<>""),IF(E30>F30,"H",IF(E30<F30,"A","D")),"") -> H
A31: 23 | B31: 2026-06-25 | C31: D | D31: Turkije | E31: 2 | F31: 2 | G31: USA | H31: =IF(AND(E31<>"",F31<>""),IF(E31>F31,"H",IF(E31<F31,"A","D")),"") -> D
A32: 24 | B32: 2026-06-25 | C32: D | D32: Paraguay | E32: 1 | F32: 1 | G32: Australia | H32: =IF(AND(E32<>"",F32<>""),IF(E32>F32,"H",IF(E32<F32,"A","D")),"") -> D
A33: 25 | B33: 2026-06-14 | C33: E | D33: Germany | E33: 3 | F33: 0 | G33: Curaçao | H33: =IF(AND(E33<>"",F33<>""),IF(E33>F33,"H",IF(E33<F33,"A","D")),"") -> H | J33: 1
A34: 26 | B34: 2026-06-14 | C34: E | D34: Ivory Coast | E34: 1 | F34: 2 | G34: Ecuador | H34: =IF(AND(E34<>"",F34<>""),IF(E34>F34,"H",IF(E34<F34,"A","D")),"") -> A | J34: 0
A35: 27 | B35: 2026-06-20 | C35: E | D35: Germany | E35: 2 | F35: 2 | G35: Ivory Coast | H35: =IF(AND(E35<>"",F35<>""),IF(E35>F35,"H",IF(E35<F35,"A","D")),"") -> D
A36: 28 | B36: 2026-06-20 | C36: E | D36: Ecuador | E36: 2 | F36: 0 | G36: Curaçao | H36: =IF(AND(E36<>"",F36<>""),IF(E36>F36,"H",IF(E36<F36,"A","D")),"") -> H
A37: 29 | B37: 2026-06-25 | C37: E | D37: Ecuador | E37: 1 | F37: 1 | G37: Germany | H37: =IF(AND(E37<>"",F37<>""),IF(E37>F37,"H",IF(E37<F37,"A","D")),"") -> D
A38: 30 | B38: 2026-06-25 | C38: E | D38: Curaçao | E38: 1 | F38: 3 | G38: Ivory Coast | H38: =IF(AND(E38<>"",F38<>""),IF(E38>F38,"H",IF(E38<F38,"A","D")),"") -> A
A39: 31 | B39: 2026-06-14 | C39: F | D39: Netherlands | E39: 2 | F39: 1 | G39: Japan | H39: =IF(AND(E39<>"",F39<>""),IF(E39>F39,"H",IF(E39<F39,"A","D")),"") -> H | J39: 0
A40: 32 | B40: 2026-06-14 | C40: F | D40: Zweden | E40: 2 | F40: 0 | G40: Tunisia | H40: =IF(AND(E40<>"",F40<>""),IF(E40>F40,"H",IF(E40<F40,"A","D")),"") -> H | J40: 1
A41: 33 | B41: 2026-06-20 | C41: F | D41: Netherlands | E41: 2 | F41: 1 | G41: Zweden | H41: =IF(AND(E41<>"",F41<>""),IF(E41>F41,"H",IF(E41<F41,"A","D")),"") -> H
A42: 34 | B42: 2026-06-20 | C42: F | D42: Tunisia | E42: 0 | F42: 2 | G42: Japan | H42: =IF(AND(E42<>"",F42<>""),IF(E42>F42,"H",IF(E42<F42,"A","D")),"") -> A
A43: 35 | B43: 2026-06-25 | C43: F | D43: Japan | E43: 2 | F43: 1 | G43: Zweden | H43: =IF(AND(E43<>"",F43<>""),IF(E43>F43,"H",IF(E43<F43,"A","D")),"") -> H
A44: 36 | B44: 2026-06-25 | C44: F | D44: Tunisia | E44: 0 | F44: 3 | G44: Netherlands | H44: =IF(AND(E44<>"",F44<>""),IF(E44>F44,"H",IF(E44<F44,"A","D")),"") -> A
A45: 37 | B45: 2026-06-15 | C45: G | D45: Belgium | E45: 2 | F45: 0 | G45: Egypt | H45: =IF(AND(E45<>"",F45<>""),IF(E45>F45,"H",IF(E45<F45,"A","D")),"") -> H | J45: 0
A46: 38 | B46: 2026-06-15 | C46: G | D46: Iran | E46: 1 | F46: 0 | G46: New Zealand | H46: =IF(AND(E46<>"",F46<>""),IF(E46>F46,"H",IF(E46<F46,"A","D")),"") -> H | J46: 0
...

Sheet Knock-out Nova 
A8: Teams laatste 32 | D8: Teams laatste 16 | G8: Teams laatste 8 | J8: Teams laatste 4 | M8: Teams Finale | P8: Winnaar
A10: 1 | B10: Ecuador | D10: 1 | E10: Ecuador | G10: 1 | H10: frankrijk | J10: 1 | K10: nederland | M10: 1 | N10: nederland | P10: 1 | Q10: portugal
A11: =A10+1 -> 2 | B11: Frankrijk | D11: =D10+1 -> 2 | E11: Frankrijk | G11: =G10+1 -> 2 | H11: nederland | J11: =J10+1 -> 2 | K11: spanje | M11: =M10+1 -> 2 | N11: portugal
A12: =A11+1 -> 3 | B12: Tsjechie | D12: =D11+1 -> 3 | E12: Tsjechie | G12: =G11+1 -> 3 | H12: spanje | J12: =J11+1 -> 3 | K12: brazilie
A13: =A12+1 -> 4 | B13: Nederland | D13: =D12+1 -> 4 | E13: Nederland | G13: =G12+1 -> 4 | H13: ivoorkust | J13: =J12+1 -> 4 | K13: portugal
A14: =A13+1 -> 5 | B14: Colombia | D14: =D13+1 -> 5 | E14: Colombia | G14: =G13+1 -> 5 | H14: brazilie
A15: =A14+1 -> 6 | B15: spanje | D15: =D14+1 -> 6 | E15: spanje | G15: =G14+1 -> 6 | H15: engeland
A16: =A15+1 -> 7 | B16: ivoorkust | D16: =D15+1 -> 7 | E16: ivoorkust | G16: =G15+1 -> 7 | H16: argentinie
A17: =A16+1 -> 8 | B17: belgie | D17: =D16+1 -> 8 | E17: belgie | G17: =G16+1 -> 8 | H17: portugal
A18: =A17+1 -> 9 | B18: brazilie | D18: =D17+1 -> 9 | E18: brazilie
A19: =A18+1 -> 10 | B19: duitsland | D19: =D18+1 -> 10 | E19: duitsland
A20: =A19+1 -> 11 | B20: mexico | D20: =D19+1 -> 11 | E20: mexico | H20: Bonus Vragen:
A21: =A20+1 -> 12 | B21: engeland | D21: =D20+1 -> 12 | E21: engeland
A22: =A21+1 -> 13 | B22: argentinie | D22: =D21+1 -> 13 | E22: argentinie | H22: 1. Topscoorder toernooi | K22: Kylian Mbappé
A23: =A22+1 -> 14 | B23: egypte | D23: =D22+1 -> 14 | E23: egypte | H23: 2. Land met 1e rode kaart | K23: Argentinie
A24: =A23+1 -> 15 | B24: zwitserland | D24: =D23+1 -> 15 | E24: zwitserland | H24: 3. Beste speler toernooi | K24: Lamine Yamal
A25: =A24+1 -> 16 | B25: portugal | D25: =D24+1 -> 16 | E25: portugal
A26: =A25+1 -> 17 | B26: schotland | H26: Totaal aantal doelpunten | K26: 254
A27: =A26+1 -> 18 | B27: zweden | H27: (bij gelijke stand)
A28: =A27+1 -> 19 | B28: canada
A29: =A28+1 -> 20 | B29: marokko
A30: =A29+1 -> 21 | B30: kroatie
A31: =A30+1 -> 22 | B31: oostenrijk
A32: =A31+1 -> 23 | B32: turkije
A33: =A32+1 -> 24 | B33: noorwegen
A34: =A33+1 -> 25 | B34: japan
A35: =A34+1 -> 26 | B35: senegal
A36: =A35+1 -> 27 | B36: bosnie herzegovina
A37: =A36+1 -> 28 | B37: algerije
A38: =A37+1 -> 29 | B38: uruguay
A39: =A38+1 -> 30 | B39: USA
... A41: =A40+1 -> 32 | B41: ghana

Sheet Groepsfase Koen N
J6: Punten
A8: Nr | B8: Datum | C8: Groep | D8: Thuis | E8: T | F8: U | G8: Uit | H8: Res
A9: 1 | B9: 2026-06-11 | C9: A | D9: Mexico | E9: 2 | F9: 0 | G9: South Africa | H9: =IF(AND(E9<>"",F9<>""),IF(E9>F9,"H",IF(E9<F9,"A","D")),"") -> H | J9: 3
A10: 2 | B10: 2026-06-11 | C10: A | D10: South Korea | E10: 2 | F10: 1 | G10: Tsjechië | H10: =IF(AND(E10<>"",F10<>""),IF(E10>F10,"H",IF(E10<F10,"A","D")),"") -> H | J10: 3
A11: 3 | B11: 2026-06-18 | C11: A | D11: Tsjechië | E11: 2 | F11: 1 | G11: South Africa | H11: =IF(AND(E11<>"",F11<>""),IF(E11>F11,"H",IF(E11<F11,"A","D")),"") -> H
A12: 4 | B12: 2026-06-18 | C12: A | D12: Mexico | E12: 2 | F12: 1 | G12: South Korea | H12: =IF(AND(E12<>"",F12<>""),IF(E12>F12,"H",IF(E12<F12,"A","D")),"") -> H
A13: 5 | B13: 2026-06-24 | C13: A | D13: Tsjechië | E13: 1 | F13: 2 | G13: Mexico | H13: =IF(AND(E13<>"",F13<>""),IF(E13>F13,"H",IF(E13<F13,"A","D")),"") -> A
A14: 6 | B14: 2026-06-24 | C14: A | D14: South Africa | E14: 1 | F14: 2 | G14: South Korea | H14: =IF(AND(E14<>"",F14<>""),IF(E14>F14,"H",IF(E14<F14,"A","D")),"") -> A
A15: 7 | B15: 2026-06-12 | C15: B | D15: Canada | E15: 2 | F15: 1 | G15: Bosnië-Herzegovina | H15: =IF(AND(E15<>"",F15<>""),IF(E15>F15,"H",IF(E15<F15,"A","D")),"") -> H | J15: 0
A16: 8 | B16: 2026-06-13 | C16: B | D16: Qatar | E16: 0 | F16: 2 | G16: Switzerland | H16: =IF(AND(E16<>"",F16<>""),IF(E16>F16,"H",IF(E16<F16,"A","D")),"") -> A | J16: 0
A17: 9 | B17: 2026-06-18 | C17: B | D17: Switzerland | E17: 2 | F17: 1 | G17: Bosnië-Herzegovina | H17: =IF(AND(E17<>"",F17<>""),IF(E17>F17,"H",IF(E17<F17,"A","D")),"") -> H
A18: 10 | B18: 2026-06-18 | C18: B | D18: Canada | E18: 3 | F18: 0 | G18: Qatar | H18: =IF(AND(E18<>"",F18<>""),IF(E18>F18,"H",IF(E18<F18,"A","D")),"") -> H
A19: 11 | B19: 2026-06-24 | C19: B | D19: Switzerland | E19: 1 | F19: 1 | G19: Canada | H19: =IF(AND(E19<>"",F19<>""),IF(E19>F19,"H",IF(E19<F19,"A","D")),"") -> D
A20: 12 | B20: 2026-06-24 | C20: B | D20: Bosnië-Herzegovina | E20: 2 | F20: 1 | G20: Qatar | H20: =IF(AND(E20<>"",F20<>""),IF(E20>F20,"H",IF(E20<F20,"A","D")),"") -> H
A21: 13 | B21: 2026-06-13 | C21: C | D21: Brazil | E21: 2 | F21: 0 | G21: Morocco | H21: =IF(AND(E21<>"",F21<>""),IF(E21>F21,"H",IF(E21<F21,"A","D")),"") -> H | J21: 0
A22: 14 | B22: 2026-06-13 | C22: C | D22: Haiti | E22: 1 | F22: 2 | G22: Scotland | H22: =IF(AND(E22<>"",F22<>""),IF(E22>F22,"H",IF(E22<F22,"A","D")),"") -> A | J22: 1
A23: 15 | B23: 2026-06-19 | C23: C | D23: Scotland | E23: 1 | F23: 2 | G23: Morocco | H23: =IF(AND(E23<>"",F23<>""),IF(E23>F23,"H",IF(E23<F23,"A","D")),"") -> A
A24: 16 | B24: 2026-06-19 | C24: C | D24: Brazil | E24: 4 | F24: 0 | G24: Haiti | H24: =IF(AND(E24<>"",F24<>""),IF(E24>F24,"H",IF(E24<F24,"A","D")),"") -> H
A25: 17 | B25: 2026-06-24 | C25: C | D25: Scotland | E25: 0 | F25: 4 | G25: Brazil | H25: =IF(AND(E25<>"",F25<>""),IF(E25>F25,"H",IF(E25<F25,"A","D")),"") -> A
A26: 18 | B26: 2026-06-24 | C26: C | D26: Morocco | E26: 2 | F26: 0 | G26: Haiti | H26: =IF(AND(E26<>"",F26<>""),IF(E26>F26,"H",IF(E26<F26,"A","D")),"") -> H
A27: 19 | B27: 2026-06-12 | C27: D | D27: USA | E27: 2 | F27: 0 | G27: Paraguay | H27: =IF(AND(E27<>"",F27<>""),IF(E27>F27,"H",IF(E27<F27,"A","D")),"") -> H | J27: 1
A28: 20 | B28: 2026-06-13 | C28: D | D28: Australia | E28: 1 | F28: 2 | G28: Turkije | H28: =IF(AND(E28<>"",F28<>""),IF(E28>F28,"H",IF(E28<F28,"A","D")),"") -> A | J28: 0
A29: 21 | B29: 2026-06-19 | C29: D | D29: USA | E29: 2 | F29: 0 | G29: Australia | H29: =IF(AND(E29<>"",F29<>""),IF(E29>F29,"H",IF(E29<F29,"A","D")),"") -> H
A30: 22 | B30: 2026-06-19 | C30: D | D30: Turkije | E30: 2 | F30: 1 | G30: Paraguay | H30: =IF(AND(E30<>"",F30<>""),IF(E30>F30,"H",IF(E30<F30,"A","D")),"") -> H
A31: 23 | B31: 2026-06-25 | C31: D | D31: Turkije | E31: 1 | F31: 2 | G31: USA | H31: =IF(AND(E31<>"",F31<>""),IF(E31>F31,"H",IF(E31<F31,"A","D")),"") -> A
A32: 24 | B32: 2026-06-25 | C32: D | D32: Paraguay | E32: 1 | F32: 1 | G32: Australia | H32: =IF(AND(E32<>"",F32<>""),IF(E32>F32,"H",IF(E32<F32,"A","D")),"") -> D
A33: 25 | B33: 2026-06-14 | C33: E | D33: Germany | E33: 4 | F33: 0 | G33: Curaçao | H33: =IF(AND(E33<>"",F33<>""),IF(E33>F33,"H",IF(E33<F33,"A","D")),"") -> H | J33: 1
A34: 26 | B34: 2026-06-14 | C34: E | D34: Ivory Coast | E34: 1 | F34: 1 | G34: Ecuador | H34: =IF(AND(E34<>"",F34<>""),IF(E34>F34,"H",IF(E34<F34,"A","D")),"") -> D | J34: 0
A35: 27 | B35: 2026-06-20 | C35: E | D35: Germany | E35: 4 | F35: 0 | G35: Ivory Coast | H35: =IF(AND(E35<>"",F35<>""),IF(E35>F35,"H",IF(E35<F35,"A","D")),"") -> H
A36: 28 | B36: 2026-06-20 | C36: E | D36: Ecuador | E36: 2 | F36: 1 | G36: Curaçao | H36: =IF(AND(E36<>"",F36<>""),IF(E36>F36,"H",IF(E36<F36,"A","D")),"") -> H
A37: 29 | B37: 2026-06-25 | C37: E | D37: Ecuador | E37: 0 | F37: 4 | G37: Germany | H37: =IF(AND(E37<>"",F37<>""),IF(E37>F37,"H",IF(E37<F37,"A","D")),"") -> A
A38: 30 | B38: 2026-06-25 | C38: E | D38: Curaçao | E38: 1 | F38: 2 | G38: Ivory Coast | H38: =IF(AND(E38<>"",F38<>""),IF(E38>F38,"H",IF(E38<F38,"A","D")),"") -> A
A39: 31 | B39: 2026-06-14 | C39: F | D39: Netherlands | E39: 2 | F39: 1 | G39: Japan | H39: =IF(AND(E39<>"",F39<>""),IF(E39>F39,"H",IF(E39<F39,"A","D")),"") -> H
A40: 32 | B40: 2026-06-14 | C40: F | D40: Zweden | E40: 1 | F40: 1 | G40: Tunisia | H40: =IF(AND(E40<>"",F40<>""),IF(E40>F40,"H",IF(E40<F40,"A","D")),"") -> D | J40: 0
A41: 33 | B41: 2026-06-20 | C41: F | D41: Netherlands | E41: 2 | F41: 0 | G41: Zweden | H41: =IF(AND(E41<>"",F41<>""),IF(E41>F41,"H",IF(E41<F41,"A","D")),"") -> H | J41: 0
A42: 34 | B42: 2026-06-20 | C42: F | D42: Tunisia | E42: 1 | F42: 2 | G42: Japan | H42: =IF(AND(E42<>"",F42<>""),IF(E42>F42,"H",IF(E42<F42,"A","D")),"") -> A
A43: 35 | B43: 2026-06-25 | C43: F | D43: Japan | E43: 2 | F43: 1 | G43: Zweden | H43: =IF(AND(E43<>"",F43<>""),IF(E43>F43,"H",IF(E43<F43,"A","D")),"") -> H
A44: 36 | B44: 2026-06-25 | C44: F | D44: Tunisia | E44: 0 | F44: 2 | G44: Netherlands | H44: =IF(AND(E44<>"",F44<>""),IF(E44>F44,"H",IF(E44<F44,"A","D")),"") -> A
A45: 37 | B45: 2026-06-15 | C45: G | D45: Belgium | E45: 2 | F45: 0 | G45: Egypt | H45: =IF(AND(E45<>"",F45<>""),IF(E45>F45,"H",IF(E45<F45,"A","D")),"") -> H | J45: 0
A46: 38 | B46: 2026-06-15 | C46: G | D46: Iran | E46: 2 | F46: 1 | G46: New Zealand | H46: =IF(AND(E46<>"",F46<>""),IF(E46>F46,"H",IF(E46<F46,"A","D")),"") -> H | J46: 0
...

Sheet Knock-out Koen N 
A8: Teams laatste 32 | D8: Teams laatste 16 | G8: Teams laatste 8 | J8: Teams laatste 4 | M8: Teams Finale | P8: Winnaar
A10: 1 | B10: Mexico | D10: 1 | E10: Brazil | G10: 1 | H10: Brazil | J10: 1 | K10: Spain | M10: 1 | N10: Spain | P10: 1 | Q10: Spain
A11: =A10+1 -> 2 | B11: South Korea | D11: =D10+1 -> 2 | E11: Germany | G11: =G10+1 -> 2 | H11: Spain | J11: =J10+1 -> 2 | K11: France | M11: =M10+1 -> 2 | N11: Portugal
A12: =A11+1 -> 3 | B12: Canada | D12: =D11+1 -> 3 | E12: Spain | G12: =G11+1 -> 3 | H12: France | J12: =J11+1 -> 3 | K12: Portugal
A13: =A12+1 -> 4 | B13: Switzerland | D13: =D12+1 -> 4 | E13: France | G13: =G12+1 -> 4 | H13: Argentina | J13: =J12+1 -> 4 | K13: Germany
A14: =A13+1 -> 5 | B14: Brazil | D14: =D13+1 -> 5 | E14: Argentina | G14: =G13+1 -> 5 | H14: Portugal
A15: =A14+1 -> 6 | B15: Morocco | D15: =D14+1 -> 6 | E15: Portugal | G15: =G14+1 -> 6 | H15: Netherlands
A16: =A15+1 -> 7 | B16: USA | D16: =D15+1 -> 7 | E16: England | G16: =G15+1 -> 7 | H16: Germany
A17: =A16+1 -> 8 | B17: Turkey | D17: =D16+1 -> 8 | E17: Netherlands | G17: =G16+1 -> 8 | H17: England
A18: =A17+1 -> 9 | B18: Germany | D18: =D17+1 -> 9 | E18: Mexico
A19: =A18+1 -> 10 | B19: Ecuador | D19: =D18+1 -> 10 | E19: USA
A20: =A19+1 -> 11 | B20: Netherlands | D20: =D19+1 -> 11 | E20: Belgium | H20: Bonus Vragen:
A21: =A20+1 -> 12 | B21: Japan | D21: =D20+1 -> 12 | E21: Morocco
A22: =A21+1 -> 13 | B22: Belgium | D22: =D21+1 -> 13 | E22: Colombia | H22: 1. Topscoorder toernooi | I22: Kylian Mbappé (France)
A23: =A22+1 -> 14 | B23: Egypt | D23: =D22+1 -> 14 | E23: Norway | H23: 2. Land met 1e rode kaart | I23: Saudi Arabia
A24: =A23+1 -> 15 | B24: Spain | D24: =D23+1 -> 15 | E24: Ecuador | H24: 3. Beste speler toernooi | I24: Lamine Yamal (Spain)
A25: =A24+1 -> 16 | B25: Uruguay | D25: =D24+1 -> 16 | E25: Croatia
A26: =A25+1 -> 17 | B26: France | H26: Totaal aantal doelpunten | I26: 274
A27: =A26+1 -> 18 | B27: Norway | H27: (bij gelijke stand)
A28: =A27+1 -> 19 | B28: Argentina
A29: =A28+1 -> 20 | B29: Austria
A30: =A29+1 -> 21 | B30: Portugal
A31: =A30+1 -> 22 | B31: Colombia
A32: =A31+1 -> 23 | B32: England
A33: =A32+1 -> 24 | B33: Croatia
A34: =A33+1 -> 25 | B34: Tsjechië
A35: =A34+1 -> 26 | B35: Bosnië-Herzegovina
A36: =A35+1 -> 27 | B36: Scotland
A37: =A36+1 -> 28 | B37: Paraguay
A38: =A37+1 -> 29 | B38: Ivory Coast
A39: =A38+1 -> 30 | B39: Sweden
... A41: =A40+1 -> 32 | B41: Senegal

Sheet Groepsfase Frederique
J6: Punten
A8: Nr | B8: Datum | C8: Groep | D8: Thuis | E8: T | F8: U | G8: Uit | H8: Res
A9: 1 | B9: 2026-06-11 | C9: A | D9: Mexico | E9: 3 | F9: 1 | G9: South Africa | H9: =IF(AND(E9<>"",F9<>""),IF(E9>F9,"H",IF(E9<F9,"A","D")),"") -> H | J9: 1
A10: 2 | B10: 2026-06-11 | C10: A | D10: South Korea | E10: 2 | F10: 0 | G10: Tsjechië | H10: =IF(AND(E10<>"",F10<>""),IF(E10>F10,"H",IF(E10<F10,"A","D")),"") -> H | J10: 1
A11: 3 | B11: 2026-06-18 | C11: A | D11: Tsjechië | E11: 1 | F11: 0 | G11: South Africa | H11: =IF(AND(E11<>"",F11<>""),IF(E11>F11,"H",IF(E11<F11,"A","D")),"") -> H
A12: 4 | B12: 2026-06-18 | C12: A | D12: Mexico | E12: 2 | F12: 1 | G12: South Korea | H12: =IF(AND(E12<>"",F12<>""),IF(E12>F12,"H",IF(E12<F12,"A","D")),"") -> H
A13: 5 | B13: 2026-06-24 | C13: A | D13: Tsjechië | E13: 1 | F13: 1 | G13: Mexico | H13: =IF(AND(E13<>"",F13<>""),IF(E13>F13,"H",IF(E13<F13,"A","D")),"") -> D
A14: 6 | B14: 2026-06-24 | C14: A | D14: South Africa | E14: 1 | F14: 0 | G14: South Korea | H14: =IF(AND(E14<>"",F14<>""),IF(E14>F14,"H",IF(E14<F14,"A","D")),"") -> H
A15: 7 | B15: 2026-06-12 | C15: B | D15: Canada | E15: 2 | F15: 0 | G15: Bosnië-Herzegovina | H15: =IF(AND(E15<>"",F15<>""),IF(E15>F15,"H",IF(E15<F15,"A","D")),"") -> H | J15: 0
A16: 8 | B16: 2026-06-13 | C16: B | D16: Qatar | E16: 0 | F16: 1 | G16: Switzerland | H16: =IF(AND(E16<>"",F16<>""),IF(E16>F16,"H",IF(E16<F16,"A","D")),"") -> A | J16: 0
A17: 9 | B17: 2026-06-18 | C17: B | D17: Switzerland | E17: 1 | F17: 1 | G17: Bosnië-Herzegovina | H17: =IF(AND(E17<>"",F17<>""),IF(E17>F17,"H",IF(E17<F17,"A","D")),"") -> D
A18: 10 | B18: 2026-06-18 | C18: B | D18: Canada | E18: 2 | F18: 0 | G18: Qatar | H18: =IF(AND(E18<>"",F18<>""),IF(E18>F18,"H",IF(E18<F18,"A","D")),"") -> H
A19: 11 | B19: 2026-06-24 | C19: B | D19: Switzerland | E19: 0 | F19: 2 | G19: Canada | H19: =IF(AND(E19<>"",F19<>""),IF(E19>F19,"H",IF(E19<F19,"A","D")),"") -> A
A20: 12 | B20: 2026-06-24 | C20: B | D20: Bosnië-Herzegovina | E20: 1 | F20: 0 | G20: Qatar | H20: =IF(AND(E20<>"",F20<>""),IF(E20>F20,"H",IF(E20<F20,"A","D")),"") -> H
A21: 13 | B21: 2026-06-13 | C21: C | D21: Brazil | E21: 3 | F21: 1 | G21: Morocco | H21: =IF(AND(E21<>"",F21<>""),IF(E21>F21,"H",IF(E21<F21,"A","D")),"") -> H | J21: 1
A22: 14 | B22: 2026-06-13 | C22: C | D22: Haiti | E22: 1 | F22: 2 | G22: Scotland | H22: =IF(AND(E22<>"",F22<>""),IF(E22>F22,"H",IF(E22<F22,"A","D")),"") -> A | J22: 1
A23: 15 | B23: 2026-06-19 | C23: C | D23: Scotland | E23: 1 | F23: 2 | G23: Morocco | H23: =IF(AND(E23<>"",F23<>""),IF(E23>F23,"H",IF(E23<F23,"A","D")),"") -> A
A24: 16 | B24: 2026-06-19 | C24: C | D24: Brazil | E24: 4 | F24: 0 | G24: Haiti | H24: =IF(AND(E24<>"",F24<>""),IF(E24>F24,"H",IF(E24<F24,"A","D")),"") -> H
A25: 17 | B25: 2026-06-24 | C25: C | D25: Scotland | E25: 0 | F25: 2 | G25: Brazil | H25: =IF(AND(E25<>"",F25<>""),IF(E25>F25,"H",IF(E25<F25,"A","D")),"") -> A
A26: 18 | B26: 2026-06-24 | C26: C | D26: Morocco | E26: 2 | F26: 0 | G26: Haiti | H26: =IF(AND(E26<>"",F26<>""),IF(E26>F26,"H",IF(E26<F26,"A","D")),"") -> H
A27: 19 | B27: 2026-06-12 | C27: D | D27: USA | E27: 3 | F27: 1 | G27: Paraguay | H27: =IF(AND(E27<>"",F27<>""),IF(E27>F27,"H",IF(E27<F27,"A","D")),"") -> H | J27: 1
A28: 20 | B28: 2026-06-13 | C28: D | D28: Australia | E28: 1 | F28: 0 | G28: Turkije | H28: =IF(AND(E28<>"",F28<>""),IF(E28>F28,"H",IF(E28<F28,"A","D")),"") -> H | J28: 1
A29: 21 | B29: 2026-06-19 | C29: D | D29: USA | E29: 1 | F29: 0 | G29: Australia | H29: =IF(AND(E29<>"",F29<>""),IF(E29>F29,"H",IF(E29<F29,"A","D")),"") -> H
A30: 22 | B30: 2026-06-19 | C30: D | D30: Turkije | E30: 2 | F30: 1 | G30: Paraguay | H30: =IF(AND(E30<>"",F30<>""),IF(E30>F30,"H",IF(E30<F30,"A","D")),"") -> H
A31: 23 | B31: 2026-06-25 | C31: D | D31: Turkije | E31: 1 | F31: 1 | G31: USA | H31: =IF(AND(E31<>"",F31<>""),IF(E31>F31,"H",IF(E31<F31,"A","D")),"") -> D
A32: 24 | B32: 2026-06-25 | C32: D | D32: Paraguay | E32: 0 | F32: 1 | G32: Australia | H32: =IF(AND(E32<>"",F32<>""),IF(E32>F32,"H",IF(E32<F32,"A","D")),"") -> A
A33: 25 | B33: 2026-06-14 | C33: E | D33: Germany | E33: 2 | F33: 0 | G33: Curaçao | H33: =IF(AND(E33<>"",F33<>""),IF(E33>F33,"H",IF(E33<F33,"A","D")),"") -> H | J33: 1
A34: 26 | B34: 2026-06-14 | C34: E | D34: Ivory Coast | E34: 0 | F34: 0 | G34: Ecuador | H34: =IF(AND(E34<>"",F34<>""),IF(E34>F34,"H",IF(E34<F34,"A","D")),"") -> D | J34: 0
A35: 27 | B35: 2026-06-20 | C35: E | D35: Germany | E35: 1 | F35: 1 | G35: Ivory Coast | H35: =IF(AND(E35<>"",F35<>""),IF(E35>F35,"H",IF(E35<F35,"A","D")),"") -> D
A36: 28 | B36: 2026-06-20 | C36: E | D36: Ecuador | E36: 0 | F36: 0 | G36: Curaçao | H36: =IF(AND(E36<>"",F36<>""),IF(E36>F36,"H",IF(E36<F36,"A","D")),"") -> D
A37: 29 | B37: 2026-06-25 | C37: E | D37: Ecuador | E37: 0 | F37: 0 | G37: Germany | H37: =IF(AND(E37<>"",F37<>""),IF(E37>F37,"H",IF(E37<F37,"A","D")),"") -> D
A38: 30 | B38: 2026-06-25 | C38: E | D38: Curaçao | E38: 0 | F38: 1 | G38: Ivory Coast | H38: =IF(AND(E38<>"",F38<>""),IF(E38>F38,"H",IF(E38<F38,"A","D")),"") -> A
A39: 31 | B39: 2026-06-14 | C39: F | D39: Netherlands | E39: 2 | F39: 0 | G39: Japan | H39: =IF(AND(E39<>"",F39<>""),IF(E39>F39,"H",IF(E39<F39,"A","D")),"") -> H | J39: 0
A40: 32 | B40: 2026-06-14 | C40: F | D40: Zweden | E40: 1 | F40: 0 | G40: Tunisia | H40: =IF(AND(E40<>"",F40<>""),IF(E40>F40,"H",IF(E40<F40,"A","D")),"") -> H | J40: 1
A41: 33 | B41: 2026-06-20 | C41: F | D41: Netherlands | E41: 2 | F41: 1 | G41: Zweden | H41: =IF(AND(E41<>"",F41<>""),IF(E41>F41,"H",IF(E41<F41,"A","D")),"") -> H
A42: 34 | B42: 2026-06-20 | C42: F | D42: Tunisia | E42: 0 | F42: 1 | G42: Japan | H42: =IF(AND(E42<>"",F42<>""),IF(E42>F42,"H",IF(E42<F42,"A","D")),"") -> A
A43: 35 | B43: 2026-06-25 | C43: F | D43: Japan | E43: 2 | F43: 2 | G43: Zweden | H43: =IF(AND(E43<>"",F43<>""),IF(E43>F43,"H",IF(E43<F43,"A","D")),"") -> D
A44: 36 | B44: 2026-06-25 | C44: F | D44: Tunisia | E44: 1 | F44: 4 | G44: Netherlands | H44: =IF(AND(E44<>"",F44<>""),IF(E44>F44,"H",IF(E44<F44,"A","D")),"") -> A
A45: 37 | B45: 2026-06-15 | C45: G | D45: Belgium | E45: 1 | F45: 0 | G45: Egypt | H45: =IF(AND(E45<>"",F45<>""),IF(E45>F45,"H",IF(E45<F45,"A","D")),"") -> H | J45: 0
A46: 38 | B46: 2026-06-15 | C46: G | D46: Iran | E46: 0 | F46: 2 | G46: New Zealand | H46: =IF(AND(E46<>"",F46<>""),IF(E46>F46,"H",IF(E46<F46,"A","D")),"") -> A | J46: 0
...

Sheet Knock-out Frederique 
A8: Teams laatste 32 | D8: Teams laatste 16 | G8: Teams laatste 8 | J8: Teams laatste 4 | M8: Teams Finale | P8: Winnaar
A10: 1 | B10: Mexico | D10: 1 | E10: Mexico | G10: 1 | H10: Nederland | J10: 1 | K10: Nederland | M10: 1 | N10: Nederland | P10: 1 | Q10: Nederland
A11: =A10+1 -> 2 | B11: Tjechië | D11: =D10+1 -> 2 | E11: Brazilië | G11: =G10+1 -> 2 | H11: Portugal | J11: =J10+1 -> 2 | K11: Portugal | M11: =M10+1 -> 2 | N11: Spanje
A12: =A11+1 -> 3 | B12: Zuid-Korea | D12: =D11+1 -> 3 | E12: USA | G12: =G11+1 -> 3 | H12: Argentinië | J12: =J11+1 -> 3 | K12: Engeland
A13: =A12+1 -> 4 | B13: Canada | D13: =D12+1 -> 4 | E13: Nederland | G13: =G12+1 -> 4 | H13: Spanje | J13: =J12+1 -> 4 | K13: Spanje
A14: =A13+1 -> 5 | B14: Zwitserland | D14: =D13+1 -> 5 | E14: Spanje | G14: =G13+1 -> 5 | H14: Ivoorkust
A15: =A14+1 -> 6 | B15: Bosnië | D15: =D14+1 -> 6 | E15: Portugal | G15: =G14+1 -> 6 | H15: Duitsland
A16: =A15+1 -> 7 | B16: Brazilië | D16: =D15+1 -> 7 | E16: België | G16: =G15+1 -> 7 | H16: Engeland
A17: =A16+1 -> 8 | B17: Marokko | D17: =D16+1 -> 8 | E17: Engeland | G17: =G16+1 -> 8 | H17: Brazilië
A18: =A17+1 -> 9 | B18: USA | D18: =D17+1 -> 9 | E18: Australië
A19: =A18+1 -> 10 | B19: Australië | D19: =D18+1 -> 10 | E19: Duitsland
A20: =A19+1 -> 11 | B20: Turkije | D20: =D19+1 -> 11 | E20: Argentinië | H20: Bonus Vragen:
A21: =A20+1 -> 12 | B21: Duitsland | D21: =D20+1 -> 12 | E21: Ecuador
A22: =A21+1 -> 13 | B22: Ivoorkust | D22: =D21+1 -> 13 | E22: Ivoorkust | H22: 1. Topscoorder toernooi | K22: Malen
A23: =A22+1 -> 14 | B23: Ecuador | D23: =D22+1 -> 14 | E23: Japan | H23: 2. Land met 1e rode kaart | K23: Marokko
A24: =A23+1 -> 15 | B24: Nederland | D24: =D23+1 -> 15 | E24: Noorwegen | H24: 3. Beste speler toernooi | K24: Ronaldo
A25: =A24+1 -> 16 | B25: Zweden | D25: =D24+1 -> 16 | E25: Kroatië
A26: =A25+1 -> 17 | B26: Japan | H26: Totaal aantal doelpunten | K26: 299
A27: =A26+1 -> 18 | B27: België | H27: (bij gelijke stand)
A28: =A27+1 -> 19 | B28: Nieuw-Zeeland
A29: =A28+1 -> 20 | B29: Egypte
A30: =A29+1 -> 21 | B30: Spanje
A31: =A30+1 -> 22 | B31: Uruguay
A32: =A31+1 -> 23 | B32: Noorwegen
A33: =A32+1 -> 24 | B33: Frankrijk
A34: =A33+1 -> 25 | B34: Senegal
A35: =A34+1 -> 26 | B35: Argentinië
A36: =A35+1 -> 27 | B36: Algerije
A37: =A36+1 -> 28 | B37: Portugal
A38: =A37+1 -> 29 | B38: Congo
A39: =A38+1 -> 30 | B39: Oezbekistan
... A41: =A40+1 -> 32 | B41: Kroatië

Sheet Groepsfase PP
J6: Punten
A8: Nr | B8: Datum | C8: Groep | D8: Thuis | E8: T | F8: U | G8: Uit | H8: Res
A9: 1 | B9: 2026-06-11 | C9: A | D9: Mexico | E9: 2 | F9: 0 | G9: South Africa | H9: =IF(AND(E9<>"",F9<>""),IF(E9>F9,"H",IF(E9<F9,"A","D")),"") -> H | J9: 3
A10: 2 | B10: 2026-06-11 | C10: A | D10: South Korea | E10: 0 | F10: 1 | G10: Tsjechië | H10: =IF(AND(E10<>"",F10<>""),IF(E10>F10,"H",IF(E10<F10,"A","D")),"") -> A | J10: 0
A11: 3 | B11: 2026-06-18 | C11: A | D11: Tsjechië | E11: 2 | F11: 0 | G11: South Africa | H11: =IF(AND(E11<>"",F11<>""),IF(E11>F11,"H",IF(E11<F11,"A","D")),"") -> H
A12: 4 | B12: 2026-06-18 | C12: A | D12: Mexico | E12: 2 | F12: 1 | G12: South Korea | H12: =IF(AND(E12<>"",F12<>""),IF(E12>F12,"H",IF(E12<F12,"A","D")),"") -> H
A13: 5 | B13: 2026-06-24 | C13: A | D13: Tsjechië | E13: 1 | F13: 1 | G13: Mexico | H13: =IF(AND(E13<>"",F13<>""),IF(E13>F13,"H",IF(E13<F13,"A","D")),"") -> D
A14: 6 | B14: 2026-06-24 | C14: A | D14: South Africa | E14: 0 | F14: 1 | G14: South Korea | H14: =IF(AND(E14<>"",F14<>""),IF(E14>F14,"H",IF(E14<F14,"A","D")),"") -> A
A15: 7 | B15: 2026-06-12 | C15: B | D15: Canada | E15: 1 | F15: 1 | G15: Bosnië-Herzegovina | H15: =IF(AND(E15<>"",F15<>""),IF(E15>F15,"H",IF(E15<F15,"A","D")),"") -> D | J15: 3
A16: 8 | B16: 2026-06-13 | C16: B | D16: Qatar | E16: 0 | F16: 2 | G16: Switzerland | H16: =IF(AND(E16<>"",F16<>""),IF(E16>F16,"H",IF(E16<F16,"A","D")),"") -> A | J16: 0
A17: 9 | B17: 2026-06-18 | C17: B | D17: Switzerland | E17: 2 | F17: 0 | G17: Bosnië-Herzegovina | H17: =IF(AND(E17<>"",F17<>""),IF(E17>F17,"H",IF(E17<F17,"A","D")),"") -> H
A18: 10 | B18: 2026-06-18 | C18: B | D18: Canada | E18: 2 | F18: 0 | G18: Qatar | H18: =IF(AND(E18<>"",F18<>""),IF(E18>F18,"H",IF(E18<F18,"A","D")),"") -> H
A19: 11 | B19: 2026-06-24 | C19: B | D19: Switzerland | E19: 1 | F19: 1 | G19: Canada | H19: =IF(AND(E19<>"",F19<>""),IF(E19>F19,"H",IF(E19<F19,"A","D")),"") -> D
A20: 12 | B20: 2026-06-24 | C20: B | D20: Bosnië-Herzegovina | E20: 2 | F20: 0 | G20: Qatar | H20: =IF(AND(E20<>"",F20<>""),IF(E20>F20,"H",IF(E20<F20,"A","D")),"") -> H
A21: 13 | B21: 2026-06-13 | C21: C | D21: Brazil | E21: 3 | F21: 1 | G21: Morocco | H21: =IF(AND(E21<>"",F21<>""),IF(E21>F21,"H",IF(E21<F21,"A","D")),"") -> H | J21: 0
A22: 14 | B22: 2026-06-13 | C22: C | D22: Haiti | E22: 0 | F22: 3 | G22: Scotland | H22: =IF(AND(E22<>"",F22<>""),IF(E22>F22,"H",IF(E22<F22,"A","D")),"") -> A | J22: 1
A23: 15 | B23: 2026-06-19 | C23: C | D23: Scotland | E23: 1 | F23: 2 | G23: Morocco | H23: =IF(AND(E23<>"",F23<>""),IF(E23>F23,"H",IF(E23<F23,"A","D")),"") -> A
A24: 16 | B24: 2026-06-19 | C24: C | D24: Brazil | E24: 5 | F24: 0 | G24: Haiti | H24: =IF(AND(E24<>"",F24<>""),IF(E24>F24,"H",IF(E24<F24,"A","D")),"") -> H
A25: 17 | B25: 2026-06-24 | C25: C | D25: Scotland | E25: 0 | F25: 2 | G25: Brazil | H25: =IF(AND(E25<>"",F25<>""),IF(E25>F25,"H",IF(E25<F25,"A","D")),"") -> A
A26: 18 | B26: 2026-06-24 | C26: C | D26: Morocco | E26: 3 | F26: 0 | G26: Haiti | H26: =IF(AND(E26<>"",F26<>""),IF(E26>F26,"H",IF(E26<F26,"A","D")),"") -> H
A27: 19 | B27: 2026-06-12 | C27: D | D27: USA | E27: 1 | F27: 1 | G27: Paraguay | H27: =IF(AND(E27<>"",F27<>""),IF(E27>F27,"H",IF(E27<F27,"A","D")),"") -> D | J27: 0
A28: 20 | B28: 2026-06-13 | C28: D | D28: Australia | E28: 1 | F28: 1 | G28: Turkije | H28: =IF(AND(E28<>"",F28<>""),IF(E28>F28,"H",IF(E28<F28,"A","D")),"") -> D | J28: 0
A29: 21 | B29: 2026-06-19 | C29: D | D29: USA | E29: 2 | F29: 1 | G29: Australia | H29: =IF(AND(E29<>"",F29<>""),IF(E29>F29,"H",IF(E29<F29,"A","D")),"") -> H
A30: 22 | B30: 2026-06-19 | C30: D | D30: Turkije | E30: 2 | F30: 1 | G30: Paraguay | H30: =IF(AND(E30<>"",F30<>""),IF(E30>F30,"H",IF(E30<F30,"A","D")),"") -> H
A31: 23 | B31: 2026-06-25 | C31: D | D31: Turkije | E31: 1 | F31: 1 | G31: USA | H31: =IF(AND(E31<>"",F31<>""),IF(E31>F31,"H",IF(E31<F31,"A","D")),"") -> D
A32: 24 | B32: 2026-06-25 | C32: D | D32: Paraguay | E32: 1 | F32: 0 | G32: Australia | H32: =IF(AND(E32<>"",F32<>""),IF(E32>F32,"H",IF(E32<F32,"A","D")),"") -> H
A33: 25 | B33: 2026-06-14 | C33: E | D33: Germany | E33: 3 | F33: 0 | G33: Curaçao | H33: =IF(AND(E33<>"",F33<>""),IF(E33>F33,"H",IF(E33<F33,"A","D")),"") -> H | J33: 1
A34: 26 | B34: 2026-06-14 | C34: E | D34: Ivory Coast | E34: 1 | F34: 1 | G34: Ecuador | H34: =IF(AND(E34<>"",F34<>""),IF(E34>F34,"H",IF(E34<F34,"A","D")),"") -> D | J34: 0
A35: 27 | B35: 2026-06-20 | C35: E | D35: Germany | E35: 2 | F35: 0 | G35: Ivory Coast | H35: =IF(AND(E35<>"",F35<>""),IF(E35>F35,"H",IF(E35<F35,"A","D")),"") -> H
